#include <iostream>

int StoiExceptionsProcessing() {
  std::string str    = "";
  int         number = 0;

  while (std::cin >> str) {
    try {
      number = std::stoi(str);
      break;
    }
    catch (const std::invalid_argument& e) {
      std::cerr << "Введено не число, попробуйте еще раз: ";
    }
    catch (const std::out_of_range& e) {
      std::cerr
        << "Введено слишком большое число, попробуйте еще раз: ";
    }
  }

  return number;
}

int StoiExceptionsProcessing(int) {
  std::string str    = "";
  int         number = 0;

  while (std::cin >> str) {
    try {
      number = std::stoi(str);
      if (number < 1 or number > 7)
        std::cerr << "Введено неподходящее число, попробуйте еще раз: ";
      else
        break;
    }
    catch (const std::invalid_argument& e) {
      std::cerr << "Введено не число, попробуйте еще раз: ";
    }
    catch (const std::out_of_range& e) {
      std::cerr
        << "Введено слишком большое число, попробуйте еще раз: ";
    }
  }

  return number;
}